Not Found: /l
Not Found: /favicon.ico
Not Found: /favicon.ico
Watching for file changes with StatReloader
Watching for file changes with StatReloader
"POST / HTTP/1.1" 200 4199
"POST / HTTP/1.1" 200 4199
Watching for file changes with StatReloader
"POST / HTTP/1.1" 200 4199
Watching for file changes with StatReloader
"POST / HTTP/1.1" 200 4199
Watching for file changes with StatReloader
"POST / HTTP/1.1" 200 4265
Watching for file changes with StatReloader
"POST / HTTP/1.1" 200 4265
Watching for file changes with StatReloader
"POST / HTTP/1.1" 200 7500
Watching for file changes with StatReloader
Watching for file changes with StatReloader
"GET / HTTP/1.1" 200 6256
"GET /static/assets/images/pp.png HTTP/1.1" 200 6864
"GET /static/assets/images/an.png HTTP/1.1" 200 6018
"GET /static/assets/images/hero-banner.png HTTP/1.1" 200 24881
Not Found: /bg.jpeg
"GET /bg.jpeg HTTP/1.1" 404 7222
"GET /base/ HTTP/1.1" 200 9971
"GET /static/assets/images/algebra.png HTTP/1.1" 304 0
"GET /static/assets/images/enc.png HTTP/1.1" 200 7844
"GET /static/assets/images/morse.png HTTP/1.1" 200 9384
"GET /static/assets/images/clock.png HTTP/1.1" 200 10377
"GET /static/assets/images/cal.png HTTP/1.1" 200 19380
"GET /static/assets/images/shima.png HTTP/1.1" 200 52801
"GET /static/assets/images/spin.png HTTP/1.1" 304 0
"GET /static/assets/images/chess.png HTTP/1.1" 304 0
"GET /static/assets/images/code.png HTTP/1.1" 200 8418
"GET /static/assets/images/download.png HTTP/1.1" 200 4544
"GET /static/assets/images/poli.png HTTP/1.1" 304 0
"GET /static/assets/images/matrix.png HTTP/1.1" 304 0
"GET /static/assets/images/quran.png HTTP/1.1" 304 0
"GET /static/assets/images/cam.png HTTP/1.1" 304 0
"GET /static/assets/images/kivy.png HTTP/1.1" 304 0
"GET /static/assets/images/trans.png HTTP/1.1" 304 0
"GET /static/assets/images/math.png HTTP/1.1" 304 0
"GET /static/assets/images/aksara.png HTTP/1.1" 304 0
"GET /static/assets/images/satuan.png HTTP/1.1" 304 0
"GET /static/assets/images/prima.png HTTP/1.1" 304 0
Not Found: /base/bg.jpeg
"GET /base/bg.jpeg HTTP/1.1" 404 7237
Not Found: /base/favicon.ico
"GET /spldtv/ HTTP/1.1" 200 2230
"GET /polino/ HTTP/1.1" 200 2639
Internal Server Error: /polino/
Traceback (most recent call last):
  File "/usr/local/lib/python3.11/dist-packages/django/core/handlers/exception.py", line 55, in inner
    response = get_response(request)
               ^^^^^^^^^^^^^^^^^^^^^
  File "/usr/local/lib/python3.11/dist-packages/django/core/handlers/base.py", line 197, in _get_response
    response = wrapped_callback(request, *callback_args, **callback_kwargs)
               ^^^^^^^^^^^^^^^^^^^^^^^^^^^^^^^^^^^^^^^^^^^^^^^^^^^^^^^^^^^^
  File "/home/secretdiscorder/djavy/bima/views.py", line 388, in polino
    poly1 = sp.Poly(polynomial1, x).as_expr()  # Convert to SymPy expression
            ^^^^^^^^^^^^^^^^^^^^^^^
  File "/usr/local/lib/python3.11/dist-packages/sympy/polys/polytools.py", line 181, in __new__
    rep = sympify(rep, evaluate=type(rep) is not str)
          ^^^^^^^^^^^^^^^^^^^^^^^^^^^^^^^^^^^^^^^^^^^
  File "/usr/local/lib/python3.11/dist-packages/sympy/core/sympify.py", line 481, in sympify
    expr = parse_expr(a, local_dict=locals, transformations=transformations, evaluate=evaluate)
           ^^^^^^^^^^^^^^^^^^^^^^^^^^^^^^^^^^^^^^^^^^^^^^^^^^^^^^^^^^^^^^^^^^^^^^^^^^^^^^^^^^^^
  File "/usr/local/lib/python3.11/dist-packages/sympy/parsing/sympy_parser.py", line 1078, in parse_expr
    code = compile(evaluateFalse(code), '<string>', 'eval') # type: ignore
                   ^^^^^^^^^^^^^^^^^^^
  File "/usr/local/lib/python3.11/dist-packages/sympy/parsing/sympy_parser.py", line 1100, in evaluateFalse
    transformed_node = ast.Expression(transformed_node.body[0].value)
                                      ~~~~~~~~~~~~~~~~~~~~~^^^
IndexError: list index out of range
"POST /polino/ HTTP/1.1" 500 97363
"GET /polino/ HTTP/1.1" 200 2639
Internal Server Error: /polino/
Traceback (most recent call last):
  File "/usr/local/lib/python3.11/dist-packages/sympy/core/sympify.py", line 481, in sympify
    expr = parse_expr(a, local_dict=locals, transformations=transformations, evaluate=evaluate)
           ^^^^^^^^^^^^^^^^^^^^^^^^^^^^^^^^^^^^^^^^^^^^^^^^^^^^^^^^^^^^^^^^^^^^^^^^^^^^^^^^^^^^
  File "/usr/local/lib/python3.11/dist-packages/sympy/parsing/sympy_parser.py", line 1078, in parse_expr
    code = compile(evaluateFalse(code), '<string>', 'eval') # type: ignore
                   ^^^^^^^^^^^^^^^^^^^
  File "/usr/local/lib/python3.11/dist-packages/sympy/parsing/sympy_parser.py", line 1097, in evaluateFalse
    node = ast.parse(s)
           ^^^^^^^^^^^^
  File "/usr/lib/python3.11/ast.py", line 50, in parse
    return compile(source, filename, mode, flags,
           ^^^^^^^^^^^^^^^^^^^^^^^^^^^^^^^^^^^^^^
  File "<unknown>", line 1
    Symbol ('x' )**Integer (2 )+Integer (3 )Symbol ('x' )+Integer (8 )
                                            ^^^^^^
SyntaxError: invalid syntax

During handling of the above exception, another exception occurred:

Traceback (most recent call last):
  File "/usr/local/lib/python3.11/dist-packages/django/core/handlers/exception.py", line 55, in inner
    response = get_response(request)
               ^^^^^^^^^^^^^^^^^^^^^
  File "/usr/local/lib/python3.11/dist-packages/django/core/handlers/base.py", line 197, in _get_response
    response = wrapped_callback(request, *callback_args, **callback_kwargs)
               ^^^^^^^^^^^^^^^^^^^^^^^^^^^^^^^^^^^^^^^^^^^^^^^^^^^^^^^^^^^^
  File "/home/secretdiscorder/djavy/bima/views.py", line 388, in polino
    poly1 = sp.Poly(polynomial1, x).as_expr()  # Convert to SymPy expression
            ^^^^^^^^^^^^^^^^^^^^^^^
  File "/usr/local/lib/python3.11/dist-packages/sympy/polys/polytools.py", line 181, in __new__
    rep = sympify(rep, evaluate=type(rep) is not str)
          ^^^^^^^^^^^^^^^^^^^^^^^^^^^^^^^^^^^^^^^^^^^
  File "/usr/local/lib/python3.11/dist-packages/sympy/core/sympify.py", line 483, in sympify
    raise SympifyError('could not parse %r' % a, exc)
sympy.core.sympify.SympifyError: Sympify of expression 'could not parse 'x**2+3x+8'' failed, because of exception being raised:
SyntaxError: invalid syntax (<unknown>, line 1)
"POST /polino/ HTTP/1.1" 500 109759
"GET /polino/ HTTP/1.1" 200 2639
"POST /polino/ HTTP/1.1" 200 2757
"GET /polino/ HTTP/1.1" 200 2639
"POST /polino/ HTTP/1.1" 200 2832
Internal Server Error: /static/assets/images/hero-banner.png
Traceback (most recent call last):
  File "/usr/local/lib/python3.11/dist-packages/django/core/handlers/exception.py", line 55, in inner
    response = get_response(request)
               ^^^^^^^^^^^^^^^^^^^^^
  File "/usr/local/lib/python3.11/dist-packages/django/core/handlers/base.py", line 197, in _get_response
    response = wrapped_callback(request, *callback_args, **callback_kwargs)
               ^^^^^^^^^^^^^^^^^^^^^^^^^^^^^^^^^^^^^^^^^^^^^^^^^^^^^^^^^^^^
  File "/usr/local/lib/python3.11/dist-packages/django/views/generic/base.py", line 104, in view
    return self.dispatch(request, *args, **kwargs)
           ^^^^^^^^^^^^^^^^^^^^^^^^^^^^^^^^^^^^^^^
  File "/usr/local/lib/python3.11/dist-packages/django/views/generic/base.py", line 143, in dispatch
    return handler(request, *args, **kwargs)
           ^^^^^^^^^^^^^^^^^^^^^^^^^^^^^^^^^
TypeError: StaticFilesView.get() got an unexpected keyword argument 'filename'
Internal Server Error: /static/assets/images/pp.png
Traceback (most recent call last):
  File "/usr/local/lib/python3.11/dist-packages/django/core/handlers/exception.py", line 55, in inner
    response = get_response(request)
               ^^^^^^^^^^^^^^^^^^^^^
  File "/usr/local/lib/python3.11/dist-packages/django/core/handlers/base.py", line 197, in _get_response
    response = wrapped_callback(request, *callback_args, **callback_kwargs)
               ^^^^^^^^^^^^^^^^^^^^^^^^^^^^^^^^^^^^^^^^^^^^^^^^^^^^^^^^^^^^
  File "/usr/local/lib/python3.11/dist-packages/django/views/generic/base.py", line 104, in view
    return self.dispatch(request, *args, **kwargs)
           ^^^^^^^^^^^^^^^^^^^^^^^^^^^^^^^^^^^^^^^
  File "/usr/local/lib/python3.11/dist-packages/django/views/generic/base.py", line 143, in dispatch
    return handler(request, *args, **kwargs)
           ^^^^^^^^^^^^^^^^^^^^^^^^^^^^^^^^^
TypeError: StaticFilesView.get() got an unexpected keyword argument 'filename'
Internal Server Error: /static/assets/images/an.png
Traceback (most recent call last):
  File "/usr/local/lib/python3.11/dist-packages/django/core/handlers/exception.py", line 55, in inner
    response = get_response(request)
               ^^^^^^^^^^^^^^^^^^^^^
  File "/usr/local/lib/python3.11/dist-packages/django/core/handlers/base.py", line 197, in _get_response
    response = wrapped_callback(request, *callback_args, **callback_kwargs)
               ^^^^^^^^^^^^^^^^^^^^^^^^^^^^^^^^^^^^^^^^^^^^^^^^^^^^^^^^^^^^
  File "/usr/local/lib/python3.11/dist-packages/django/views/generic/base.py", line 104, in view
    return self.dispatch(request, *args, **kwargs)
           ^^^^^^^^^^^^^^^^^^^^^^^^^^^^^^^^^^^^^^^
  File "/usr/local/lib/python3.11/dist-packages/django/views/generic/base.py", line 143, in dispatch
    return handler(request, *args, **kwargs)
           ^^^^^^^^^^^^^^^^^^^^^^^^^^^^^^^^^
TypeError: StaticFilesView.get() got an unexpected keyword argument 'filename'
Not Found: /bg.jpeg
Internal Server Error: /static/assets/images/hero-banner.png
Traceback (most recent call last):
  File "/usr/local/lib/python3.11/dist-packages/django/core/handlers/exception.py", line 55, in inner
    response = get_response(request)
               ^^^^^^^^^^^^^^^^^^^^^
  File "/usr/local/lib/python3.11/dist-packages/django/core/handlers/base.py", line 197, in _get_response
    response = wrapped_callback(request, *callback_args, **callback_kwargs)
               ^^^^^^^^^^^^^^^^^^^^^^^^^^^^^^^^^^^^^^^^^^^^^^^^^^^^^^^^^^^^
  File "/usr/local/lib/python3.11/dist-packages/django/views/generic/base.py", line 104, in view
    return self.dispatch(request, *args, **kwargs)
           ^^^^^^^^^^^^^^^^^^^^^^^^^^^^^^^^^^^^^^^
  File "/usr/local/lib/python3.11/dist-packages/django/views/generic/base.py", line 143, in dispatch
    return handler(request, *args, **kwargs)
           ^^^^^^^^^^^^^^^^^^^^^^^^^^^^^^^^^
TypeError: StaticFilesView.get() got an unexpected keyword argument 'filename'
Internal Server Error: /static/assets/images/pp.png
Traceback (most recent call last):
  File "/usr/local/lib/python3.11/dist-packages/django/core/handlers/exception.py", line 55, in inner
    response = get_response(request)
               ^^^^^^^^^^^^^^^^^^^^^
  File "/usr/local/lib/python3.11/dist-packages/django/core/handlers/base.py", line 197, in _get_response
    response = wrapped_callback(request, *callback_args, **callback_kwargs)
               ^^^^^^^^^^^^^^^^^^^^^^^^^^^^^^^^^^^^^^^^^^^^^^^^^^^^^^^^^^^^
  File "/usr/local/lib/python3.11/dist-packages/django/views/generic/base.py", line 104, in view
    return self.dispatch(request, *args, **kwargs)
           ^^^^^^^^^^^^^^^^^^^^^^^^^^^^^^^^^^^^^^^
  File "/usr/local/lib/python3.11/dist-packages/django/views/generic/base.py", line 143, in dispatch
    return handler(request, *args, **kwargs)
           ^^^^^^^^^^^^^^^^^^^^^^^^^^^^^^^^^
TypeError: StaticFilesView.get() got an unexpected keyword argument 'filename'
Internal Server Error: /static/assets/images/an.png
Traceback (most recent call last):
  File "/usr/local/lib/python3.11/dist-packages/django/core/handlers/exception.py", line 55, in inner
    response = get_response(request)
               ^^^^^^^^^^^^^^^^^^^^^
  File "/usr/local/lib/python3.11/dist-packages/django/core/handlers/base.py", line 197, in _get_response
    response = wrapped_callback(request, *callback_args, **callback_kwargs)
               ^^^^^^^^^^^^^^^^^^^^^^^^^^^^^^^^^^^^^^^^^^^^^^^^^^^^^^^^^^^^
  File "/usr/local/lib/python3.11/dist-packages/django/views/generic/base.py", line 104, in view
    return self.dispatch(request, *args, **kwargs)
           ^^^^^^^^^^^^^^^^^^^^^^^^^^^^^^^^^^^^^^^
  File "/usr/local/lib/python3.11/dist-packages/django/views/generic/base.py", line 143, in dispatch
    return handler(request, *args, **kwargs)
           ^^^^^^^^^^^^^^^^^^^^^^^^^^^^^^^^^
TypeError: StaticFilesView.get() got an unexpected keyword argument 'filename'
Not Found: /bg.jpeg
Internal Server Error: /static/assets/images/hero-banner.png
Traceback (most recent call last):
  File "/usr/local/lib/python3.11/dist-packages/django/core/handlers/exception.py", line 55, in inner
    response = get_response(request)
               ^^^^^^^^^^^^^^^^^^^^^
  File "/usr/local/lib/python3.11/dist-packages/django/core/handlers/base.py", line 197, in _get_response
    response = wrapped_callback(request, *callback_args, **callback_kwargs)
               ^^^^^^^^^^^^^^^^^^^^^^^^^^^^^^^^^^^^^^^^^^^^^^^^^^^^^^^^^^^^
  File "/usr/local/lib/python3.11/dist-packages/django/views/generic/base.py", line 104, in view
    return self.dispatch(request, *args, **kwargs)
           ^^^^^^^^^^^^^^^^^^^^^^^^^^^^^^^^^^^^^^^
  File "/usr/local/lib/python3.11/dist-packages/django/views/generic/base.py", line 143, in dispatch
    return handler(request, *args, **kwargs)
           ^^^^^^^^^^^^^^^^^^^^^^^^^^^^^^^^^
TypeError: StaticFilesView.get() got an unexpected keyword argument 'filename'
Internal Server Error: /static/assets/images/pp.png
Traceback (most recent call last):
  File "/usr/local/lib/python3.11/dist-packages/django/core/handlers/exception.py", line 55, in inner
    response = get_response(request)
               ^^^^^^^^^^^^^^^^^^^^^
  File "/usr/local/lib/python3.11/dist-packages/django/core/handlers/base.py", line 197, in _get_response
    response = wrapped_callback(request, *callback_args, **callback_kwargs)
               ^^^^^^^^^^^^^^^^^^^^^^^^^^^^^^^^^^^^^^^^^^^^^^^^^^^^^^^^^^^^
  File "/usr/local/lib/python3.11/dist-packages/django/views/generic/base.py", line 104, in view
    return self.dispatch(request, *args, **kwargs)
           ^^^^^^^^^^^^^^^^^^^^^^^^^^^^^^^^^^^^^^^
  File "/usr/local/lib/python3.11/dist-packages/django/views/generic/base.py", line 143, in dispatch
    return handler(request, *args, **kwargs)
           ^^^^^^^^^^^^^^^^^^^^^^^^^^^^^^^^^
TypeError: StaticFilesView.get() got an unexpected keyword argument 'filename'
Internal Server Error: /static/assets/images/an.png
Traceback (most recent call last):
  File "/usr/local/lib/python3.11/dist-packages/django/core/handlers/exception.py", line 55, in inner
    response = get_response(request)
               ^^^^^^^^^^^^^^^^^^^^^
  File "/usr/local/lib/python3.11/dist-packages/django/core/handlers/base.py", line 197, in _get_response
    response = wrapped_callback(request, *callback_args, **callback_kwargs)
               ^^^^^^^^^^^^^^^^^^^^^^^^^^^^^^^^^^^^^^^^^^^^^^^^^^^^^^^^^^^^
  File "/usr/local/lib/python3.11/dist-packages/django/views/generic/base.py", line 104, in view
    return self.dispatch(request, *args, **kwargs)
           ^^^^^^^^^^^^^^^^^^^^^^^^^^^^^^^^^^^^^^^
  File "/usr/local/lib/python3.11/dist-packages/django/views/generic/base.py", line 143, in dispatch
    return handler(request, *args, **kwargs)
           ^^^^^^^^^^^^^^^^^^^^^^^^^^^^^^^^^
TypeError: StaticFilesView.get() got an unexpected keyword argument 'filename'
Not Found: /bg.jpeg
Internal Server Error: /static/assets/images/hero-banner.png
Traceback (most recent call last):
  File "/usr/local/lib/python3.11/dist-packages/django/core/handlers/exception.py", line 55, in inner
    response = get_response(request)
               ^^^^^^^^^^^^^^^^^^^^^
  File "/usr/local/lib/python3.11/dist-packages/django/core/handlers/base.py", line 197, in _get_response
    response = wrapped_callback(request, *callback_args, **callback_kwargs)
               ^^^^^^^^^^^^^^^^^^^^^^^^^^^^^^^^^^^^^^^^^^^^^^^^^^^^^^^^^^^^
  File "/usr/local/lib/python3.11/dist-packages/django/views/generic/base.py", line 104, in view
    return self.dispatch(request, *args, **kwargs)
           ^^^^^^^^^^^^^^^^^^^^^^^^^^^^^^^^^^^^^^^
  File "/usr/local/lib/python3.11/dist-packages/django/views/generic/base.py", line 143, in dispatch
    return handler(request, *args, **kwargs)
           ^^^^^^^^^^^^^^^^^^^^^^^^^^^^^^^^^
TypeError: StaticFilesView.get() got an unexpected keyword argument 'filename'
Internal Server Error: /static/assets/images/hero-banner.png
Traceback (most recent call last):
  File "/usr/local/lib/python3.11/dist-packages/django/core/handlers/exception.py", line 55, in inner
    response = get_response(request)
               ^^^^^^^^^^^^^^^^^^^^^
  File "/usr/local/lib/python3.11/dist-packages/django/core/handlers/base.py", line 197, in _get_response
    response = wrapped_callback(request, *callback_args, **callback_kwargs)
               ^^^^^^^^^^^^^^^^^^^^^^^^^^^^^^^^^^^^^^^^^^^^^^^^^^^^^^^^^^^^
  File "/usr/local/lib/python3.11/dist-packages/django/views/generic/base.py", line 104, in view
    return self.dispatch(request, *args, **kwargs)
           ^^^^^^^^^^^^^^^^^^^^^^^^^^^^^^^^^^^^^^^
  File "/usr/local/lib/python3.11/dist-packages/django/views/generic/base.py", line 143, in dispatch
    return handler(request, *args, **kwargs)
           ^^^^^^^^^^^^^^^^^^^^^^^^^^^^^^^^^
TypeError: StaticFilesView.get() got an unexpected keyword argument 'filename'
Internal Server Error: /static/assets/images/hero-banner.png
Traceback (most recent call last):
  File "/usr/local/lib/python3.11/dist-packages/django/core/handlers/exception.py", line 55, in inner
    response = get_response(request)
               ^^^^^^^^^^^^^^^^^^^^^
  File "/usr/local/lib/python3.11/dist-packages/django/core/handlers/base.py", line 197, in _get_response
    response = wrapped_callback(request, *callback_args, **callback_kwargs)
               ^^^^^^^^^^^^^^^^^^^^^^^^^^^^^^^^^^^^^^^^^^^^^^^^^^^^^^^^^^^^
  File "/usr/local/lib/python3.11/dist-packages/django/views/generic/base.py", line 104, in view
    return self.dispatch(request, *args, **kwargs)
           ^^^^^^^^^^^^^^^^^^^^^^^^^^^^^^^^^^^^^^^
  File "/usr/local/lib/python3.11/dist-packages/django/views/generic/base.py", line 143, in dispatch
    return handler(request, *args, **kwargs)
           ^^^^^^^^^^^^^^^^^^^^^^^^^^^^^^^^^
TypeError: StaticFilesView.get() got an unexpected keyword argument 'filename'
Internal Server Error: /static/assets/images/hero-banner.png
Traceback (most recent call last):
  File "/usr/local/lib/python3.11/dist-packages/django/core/handlers/exception.py", line 55, in inner
    response = get_response(request)
               ^^^^^^^^^^^^^^^^^^^^^
  File "/usr/local/lib/python3.11/dist-packages/django/core/handlers/base.py", line 197, in _get_response
    response = wrapped_callback(request, *callback_args, **callback_kwargs)
               ^^^^^^^^^^^^^^^^^^^^^^^^^^^^^^^^^^^^^^^^^^^^^^^^^^^^^^^^^^^^
  File "/usr/local/lib/python3.11/dist-packages/django/views/generic/base.py", line 104, in view
    return self.dispatch(request, *args, **kwargs)
           ^^^^^^^^^^^^^^^^^^^^^^^^^^^^^^^^^^^^^^^
  File "/usr/local/lib/python3.11/dist-packages/django/views/generic/base.py", line 143, in dispatch
    return handler(request, *args, **kwargs)
           ^^^^^^^^^^^^^^^^^^^^^^^^^^^^^^^^^
TypeError: StaticFilesView.get() got an unexpected keyword argument 'filename'
Internal Server Error: /static/assets/images/hero-banner.png
Traceback (most recent call last):
  File "/usr/local/lib/python3.11/dist-packages/django/core/handlers/exception.py", line 55, in inner
    response = get_response(request)
               ^^^^^^^^^^^^^^^^^^^^^
  File "/usr/local/lib/python3.11/dist-packages/django/core/handlers/base.py", line 197, in _get_response
    response = wrapped_callback(request, *callback_args, **callback_kwargs)
               ^^^^^^^^^^^^^^^^^^^^^^^^^^^^^^^^^^^^^^^^^^^^^^^^^^^^^^^^^^^^
  File "/usr/local/lib/python3.11/dist-packages/django/views/generic/base.py", line 104, in view
    return self.dispatch(request, *args, **kwargs)
           ^^^^^^^^^^^^^^^^^^^^^^^^^^^^^^^^^^^^^^^
  File "/usr/local/lib/python3.11/dist-packages/django/views/generic/base.py", line 143, in dispatch
    return handler(request, *args, **kwargs)
           ^^^^^^^^^^^^^^^^^^^^^^^^^^^^^^^^^
TypeError: StaticFilesView.get() got an unexpected keyword argument 'filename'
Internal Server Error: /static/assets/images/pp.png
Traceback (most recent call last):
  File "/usr/local/lib/python3.11/dist-packages/django/core/handlers/exception.py", line 55, in inner
    response = get_response(request)
               ^^^^^^^^^^^^^^^^^^^^^
  File "/usr/local/lib/python3.11/dist-packages/django/core/handlers/base.py", line 197, in _get_response
    response = wrapped_callback(request, *callback_args, **callback_kwargs)
               ^^^^^^^^^^^^^^^^^^^^^^^^^^^^^^^^^^^^^^^^^^^^^^^^^^^^^^^^^^^^
  File "/usr/local/lib/python3.11/dist-packages/django/views/generic/base.py", line 104, in view
    return self.dispatch(request, *args, **kwargs)
           ^^^^^^^^^^^^^^^^^^^^^^^^^^^^^^^^^^^^^^^
  File "/usr/local/lib/python3.11/dist-packages/django/views/generic/base.py", line 143, in dispatch
    return handler(request, *args, **kwargs)
           ^^^^^^^^^^^^^^^^^^^^^^^^^^^^^^^^^
TypeError: StaticFilesView.get() got an unexpected keyword argument 'filename'
Internal Server Error: /static/assets/images/an.png
Traceback (most recent call last):
  File "/usr/local/lib/python3.11/dist-packages/django/core/handlers/exception.py", line 55, in inner
    response = get_response(request)
               ^^^^^^^^^^^^^^^^^^^^^
  File "/usr/local/lib/python3.11/dist-packages/django/core/handlers/base.py", line 197, in _get_response
    response = wrapped_callback(request, *callback_args, **callback_kwargs)
               ^^^^^^^^^^^^^^^^^^^^^^^^^^^^^^^^^^^^^^^^^^^^^^^^^^^^^^^^^^^^
  File "/usr/local/lib/python3.11/dist-packages/django/views/generic/base.py", line 104, in view
    return self.dispatch(request, *args, **kwargs)
           ^^^^^^^^^^^^^^^^^^^^^^^^^^^^^^^^^^^^^^^
  File "/usr/local/lib/python3.11/dist-packages/django/views/generic/base.py", line 143, in dispatch
    return handler(request, *args, **kwargs)
           ^^^^^^^^^^^^^^^^^^^^^^^^^^^^^^^^^
TypeError: StaticFilesView.get() got an unexpected keyword argument 'filename'
Not Found: /bg.jpeg
Internal Server Error: /static/assets/images/hero-banner.png
Traceback (most recent call last):
  File "/usr/local/lib/python3.11/dist-packages/django/core/handlers/exception.py", line 55, in inner
    response = get_response(request)
               ^^^^^^^^^^^^^^^^^^^^^
  File "/usr/local/lib/python3.11/dist-packages/django/core/handlers/base.py", line 197, in _get_response
    response = wrapped_callback(request, *callback_args, **callback_kwargs)
               ^^^^^^^^^^^^^^^^^^^^^^^^^^^^^^^^^^^^^^^^^^^^^^^^^^^^^^^^^^^^
  File "/usr/local/lib/python3.11/dist-packages/django/views/generic/base.py", line 104, in view
    return self.dispatch(request, *args, **kwargs)
           ^^^^^^^^^^^^^^^^^^^^^^^^^^^^^^^^^^^^^^^
  File "/usr/local/lib/python3.11/dist-packages/django/views/generic/base.py", line 143, in dispatch
    return handler(request, *args, **kwargs)
           ^^^^^^^^^^^^^^^^^^^^^^^^^^^^^^^^^
TypeError: StaticFilesView.get() got an unexpected keyword argument 'filename'
Not Found: /bg.jpeg
Not Found: /favicon.ico
Not Found: /bg.jpeg
Not Found: /bg.jpeg
Not Found: /bg.jpeg
Not Found: /bg.jpeg
Not Found: /bg.jpeg
Not Found: /bg.jpeg
Not Found: /profile/lagu.mp3
- Broken pipe from ('127.0.0.1', 60836)
Not Found: /static/assets/images/aksara.png
Not Found: /static/assets/images/morse.png
Not Found: /static/assets/images/cal.png
Not Found: /static/assets/images/code.png
Not Found: /bg.jpeg
Not Found: /static/assets/images/aksara.png
Not Found: /static/assets/images/morse.png
Not Found: /static/assets/images/cal.png
Not Found: /static/assets/images/code.png
Not Found: /bg.jpeg
Internal Server Error: /static/assets/images/aksara.png
Traceback (most recent call last):
  File "/usr/local/lib/python3.11/dist-packages/django/core/handlers/exception.py", line 55, in inner
    response = get_response(request)
               ^^^^^^^^^^^^^^^^^^^^^
  File "/usr/local/lib/python3.11/dist-packages/django/core/handlers/base.py", line 197, in _get_response
    response = wrapped_callback(request, *callback_args, **callback_kwargs)
               ^^^^^^^^^^^^^^^^^^^^^^^^^^^^^^^^^^^^^^^^^^^^^^^^^^^^^^^^^^^^
  File "/usr/local/lib/python3.11/dist-packages/django/views/generic/base.py", line 104, in view
    return self.dispatch(request, *args, **kwargs)
           ^^^^^^^^^^^^^^^^^^^^^^^^^^^^^^^^^^^^^^^
  File "/usr/local/lib/python3.11/dist-packages/django/views/generic/base.py", line 143, in dispatch
    return handler(request, *args, **kwargs)
           ^^^^^^^^^^^^^^^^^^^^^^^^^^^^^^^^^
  File "/home/secretdiscorder/djavy/bima/views.py", line 26, in get
    static_dir = settings.BASE_DIR / 'bima/static/'
                 ^^^^^^^^
NameError: name 'settings' is not defined
Internal Server Error: /static/assets/images/morse.png
Traceback (most recent call last):
  File "/usr/local/lib/python3.11/dist-packages/django/core/handlers/exception.py", line 55, in inner
    response = get_response(request)
               ^^^^^^^^^^^^^^^^^^^^^
  File "/usr/local/lib/python3.11/dist-packages/django/core/handlers/base.py", line 197, in _get_response
    response = wrapped_callback(request, *callback_args, **callback_kwargs)
               ^^^^^^^^^^^^^^^^^^^^^^^^^^^^^^^^^^^^^^^^^^^^^^^^^^^^^^^^^^^^
  File "/usr/local/lib/python3.11/dist-packages/django/views/generic/base.py", line 104, in view
    return self.dispatch(request, *args, **kwargs)
           ^^^^^^^^^^^^^^^^^^^^^^^^^^^^^^^^^^^^^^^
  File "/usr/local/lib/python3.11/dist-packages/django/views/generic/base.py", line 143, in dispatch
    return handler(request, *args, **kwargs)
           ^^^^^^^^^^^^^^^^^^^^^^^^^^^^^^^^^
  File "/home/secretdiscorder/djavy/bima/views.py", line 26, in get
    static_dir = settings.BASE_DIR / 'bima/static/'
                 ^^^^^^^^
NameError: name 'settings' is not defined
Internal Server Error: /static/assets/images/cal.png
Traceback (most recent call last):
  File "/usr/local/lib/python3.11/dist-packages/django/core/handlers/exception.py", line 55, in inner
    response = get_response(request)
               ^^^^^^^^^^^^^^^^^^^^^
  File "/usr/local/lib/python3.11/dist-packages/django/core/handlers/base.py", line 197, in _get_response
    response = wrapped_callback(request, *callback_args, **callback_kwargs)
               ^^^^^^^^^^^^^^^^^^^^^^^^^^^^^^^^^^^^^^^^^^^^^^^^^^^^^^^^^^^^
  File "/usr/local/lib/python3.11/dist-packages/django/views/generic/base.py", line 104, in view
    return self.dispatch(request, *args, **kwargs)
           ^^^^^^^^^^^^^^^^^^^^^^^^^^^^^^^^^^^^^^^
  File "/usr/local/lib/python3.11/dist-packages/django/views/generic/base.py", line 143, in dispatch
    return handler(request, *args, **kwargs)
           ^^^^^^^^^^^^^^^^^^^^^^^^^^^^^^^^^
  File "/home/secretdiscorder/djavy/bima/views.py", line 26, in get
    static_dir = settings.BASE_DIR / 'bima/static/'
                 ^^^^^^^^
NameError: name 'settings' is not defined
Internal Server Error: /static/assets/images/code.png
Traceback (most recent call last):
  File "/usr/local/lib/python3.11/dist-packages/django/core/handlers/exception.py", line 55, in inner
    response = get_response(request)
               ^^^^^^^^^^^^^^^^^^^^^
  File "/usr/local/lib/python3.11/dist-packages/django/core/handlers/base.py", line 197, in _get_response
    response = wrapped_callback(request, *callback_args, **callback_kwargs)
               ^^^^^^^^^^^^^^^^^^^^^^^^^^^^^^^^^^^^^^^^^^^^^^^^^^^^^^^^^^^^
  File "/usr/local/lib/python3.11/dist-packages/django/views/generic/base.py", line 104, in view
    return self.dispatch(request, *args, **kwargs)
           ^^^^^^^^^^^^^^^^^^^^^^^^^^^^^^^^^^^^^^^
  File "/usr/local/lib/python3.11/dist-packages/django/views/generic/base.py", line 143, in dispatch
    return handler(request, *args, **kwargs)
           ^^^^^^^^^^^^^^^^^^^^^^^^^^^^^^^^^
  File "/home/secretdiscorder/djavy/bima/views.py", line 26, in get
    static_dir = settings.BASE_DIR / 'bima/static/'
                 ^^^^^^^^
NameError: name 'settings' is not defined
Not Found: /bg.jpeg
Internal Server Error: /static/assets/images/aksara.png
Traceback (most recent call last):
  File "/usr/local/lib/python3.11/dist-packages/django/core/handlers/exception.py", line 55, in inner
    response = get_response(request)
               ^^^^^^^^^^^^^^^^^^^^^
  File "/usr/local/lib/python3.11/dist-packages/django/core/handlers/base.py", line 197, in _get_response
    response = wrapped_callback(request, *callback_args, **callback_kwargs)
               ^^^^^^^^^^^^^^^^^^^^^^^^^^^^^^^^^^^^^^^^^^^^^^^^^^^^^^^^^^^^
  File "/usr/local/lib/python3.11/dist-packages/django/views/generic/base.py", line 104, in view
    return self.dispatch(request, *args, **kwargs)
           ^^^^^^^^^^^^^^^^^^^^^^^^^^^^^^^^^^^^^^^
  File "/usr/local/lib/python3.11/dist-packages/django/views/generic/base.py", line 143, in dispatch
    return handler(request, *args, **kwargs)
           ^^^^^^^^^^^^^^^^^^^^^^^^^^^^^^^^^
  File "/home/secretdiscorder/djavy/bima/views.py", line 26, in get
    static_dir = settings.BASE_DIR / 'bima/static/'
                 ^^^^^^^^
NameError: name 'settings' is not defined
Internal Server Error: /static/assets/images/morse.png
Traceback (most recent call last):
  File "/usr/local/lib/python3.11/dist-packages/django/core/handlers/exception.py", line 55, in inner
    response = get_response(request)
               ^^^^^^^^^^^^^^^^^^^^^
  File "/usr/local/lib/python3.11/dist-packages/django/core/handlers/base.py", line 197, in _get_response
    response = wrapped_callback(request, *callback_args, **callback_kwargs)
               ^^^^^^^^^^^^^^^^^^^^^^^^^^^^^^^^^^^^^^^^^^^^^^^^^^^^^^^^^^^^
  File "/usr/local/lib/python3.11/dist-packages/django/views/generic/base.py", line 104, in view
    return self.dispatch(request, *args, **kwargs)
           ^^^^^^^^^^^^^^^^^^^^^^^^^^^^^^^^^^^^^^^
  File "/usr/local/lib/python3.11/dist-packages/django/views/generic/base.py", line 143, in dispatch
    return handler(request, *args, **kwargs)
           ^^^^^^^^^^^^^^^^^^^^^^^^^^^^^^^^^
  File "/home/secretdiscorder/djavy/bima/views.py", line 26, in get
    static_dir = settings.BASE_DIR / 'bima/static/'
                 ^^^^^^^^
NameError: name 'settings' is not defined
Internal Server Error: /static/assets/images/cal.png
Traceback (most recent call last):
  File "/usr/local/lib/python3.11/dist-packages/django/core/handlers/exception.py", line 55, in inner
    response = get_response(request)
               ^^^^^^^^^^^^^^^^^^^^^
  File "/usr/local/lib/python3.11/dist-packages/django/core/handlers/base.py", line 197, in _get_response
    response = wrapped_callback(request, *callback_args, **callback_kwargs)
               ^^^^^^^^^^^^^^^^^^^^^^^^^^^^^^^^^^^^^^^^^^^^^^^^^^^^^^^^^^^^
  File "/usr/local/lib/python3.11/dist-packages/django/views/generic/base.py", line 104, in view
    return self.dispatch(request, *args, **kwargs)
           ^^^^^^^^^^^^^^^^^^^^^^^^^^^^^^^^^^^^^^^
  File "/usr/local/lib/python3.11/dist-packages/django/views/generic/base.py", line 143, in dispatch
    return handler(request, *args, **kwargs)
           ^^^^^^^^^^^^^^^^^^^^^^^^^^^^^^^^^
  File "/home/secretdiscorder/djavy/bima/views.py", line 26, in get
    static_dir = settings.BASE_DIR / 'bima/static/'
                 ^^^^^^^^
NameError: name 'settings' is not defined
Internal Server Error: /static/assets/images/code.png
Traceback (most recent call last):
  File "/usr/local/lib/python3.11/dist-packages/django/core/handlers/exception.py", line 55, in inner
    response = get_response(request)
               ^^^^^^^^^^^^^^^^^^^^^
  File "/usr/local/lib/python3.11/dist-packages/django/core/handlers/base.py", line 197, in _get_response
    response = wrapped_callback(request, *callback_args, **callback_kwargs)
               ^^^^^^^^^^^^^^^^^^^^^^^^^^^^^^^^^^^^^^^^^^^^^^^^^^^^^^^^^^^^
  File "/usr/local/lib/python3.11/dist-packages/django/views/generic/base.py", line 104, in view
    return self.dispatch(request, *args, **kwargs)
           ^^^^^^^^^^^^^^^^^^^^^^^^^^^^^^^^^^^^^^^
  File "/usr/local/lib/python3.11/dist-packages/django/views/generic/base.py", line 143, in dispatch
    return handler(request, *args, **kwargs)
           ^^^^^^^^^^^^^^^^^^^^^^^^^^^^^^^^^
  File "/home/secretdiscorder/djavy/bima/views.py", line 26, in get
    static_dir = settings.BASE_DIR / 'bima/static/'
                 ^^^^^^^^
NameError: name 'settings' is not defined
Not Found: /bg.jpeg
Internal Server Error: /static/assets/images/aksara.png
Traceback (most recent call last):
  File "/usr/local/lib/python3.11/dist-packages/django/core/handlers/exception.py", line 55, in inner
    response = get_response(request)
               ^^^^^^^^^^^^^^^^^^^^^
  File "/usr/local/lib/python3.11/dist-packages/django/core/handlers/base.py", line 197, in _get_response
    response = wrapped_callback(request, *callback_args, **callback_kwargs)
               ^^^^^^^^^^^^^^^^^^^^^^^^^^^^^^^^^^^^^^^^^^^^^^^^^^^^^^^^^^^^
  File "/usr/local/lib/python3.11/dist-packages/django/views/generic/base.py", line 104, in view
    return self.dispatch(request, *args, **kwargs)
           ^^^^^^^^^^^^^^^^^^^^^^^^^^^^^^^^^^^^^^^
  File "/usr/local/lib/python3.11/dist-packages/django/views/generic/base.py", line 143, in dispatch
    return handler(request, *args, **kwargs)
           ^^^^^^^^^^^^^^^^^^^^^^^^^^^^^^^^^
  File "/home/secretdiscorder/djavy/bima/views.py", line 27, in get
    file_path = os.path.join(static_dir, filename)
                ^^
NameError: name 'os' is not defined
Internal Server Error: /static/assets/images/morse.png
Traceback (most recent call last):
  File "/usr/local/lib/python3.11/dist-packages/django/core/handlers/exception.py", line 55, in inner
    response = get_response(request)
               ^^^^^^^^^^^^^^^^^^^^^
  File "/usr/local/lib/python3.11/dist-packages/django/core/handlers/base.py", line 197, in _get_response
    response = wrapped_callback(request, *callback_args, **callback_kwargs)
               ^^^^^^^^^^^^^^^^^^^^^^^^^^^^^^^^^^^^^^^^^^^^^^^^^^^^^^^^^^^^
  File "/usr/local/lib/python3.11/dist-packages/django/views/generic/base.py", line 104, in view
    return self.dispatch(request, *args, **kwargs)
           ^^^^^^^^^^^^^^^^^^^^^^^^^^^^^^^^^^^^^^^
  File "/usr/local/lib/python3.11/dist-packages/django/views/generic/base.py", line 143, in dispatch
    return handler(request, *args, **kwargs)
           ^^^^^^^^^^^^^^^^^^^^^^^^^^^^^^^^^
  File "/home/secretdiscorder/djavy/bima/views.py", line 27, in get
    file_path = os.path.join(static_dir, filename)
                ^^
NameError: name 'os' is not defined
Internal Server Error: /static/assets/images/cal.png
Traceback (most recent call last):
  File "/usr/local/lib/python3.11/dist-packages/django/core/handlers/exception.py", line 55, in inner
    response = get_response(request)
               ^^^^^^^^^^^^^^^^^^^^^
  File "/usr/local/lib/python3.11/dist-packages/django/core/handlers/base.py", line 197, in _get_response
    response = wrapped_callback(request, *callback_args, **callback_kwargs)
               ^^^^^^^^^^^^^^^^^^^^^^^^^^^^^^^^^^^^^^^^^^^^^^^^^^^^^^^^^^^^
  File "/usr/local/lib/python3.11/dist-packages/django/views/generic/base.py", line 104, in view
    return self.dispatch(request, *args, **kwargs)
           ^^^^^^^^^^^^^^^^^^^^^^^^^^^^^^^^^^^^^^^
  File "/usr/local/lib/python3.11/dist-packages/django/views/generic/base.py", line 143, in dispatch
    return handler(request, *args, **kwargs)
           ^^^^^^^^^^^^^^^^^^^^^^^^^^^^^^^^^
  File "/home/secretdiscorder/djavy/bima/views.py", line 27, in get
    file_path = os.path.join(static_dir, filename)
                ^^
NameError: name 'os' is not defined
Internal Server Error: /static/assets/images/code.png
Traceback (most recent call last):
  File "/usr/local/lib/python3.11/dist-packages/django/core/handlers/exception.py", line 55, in inner
    response = get_response(request)
               ^^^^^^^^^^^^^^^^^^^^^
  File "/usr/local/lib/python3.11/dist-packages/django/core/handlers/base.py", line 197, in _get_response
    response = wrapped_callback(request, *callback_args, **callback_kwargs)
               ^^^^^^^^^^^^^^^^^^^^^^^^^^^^^^^^^^^^^^^^^^^^^^^^^^^^^^^^^^^^
  File "/usr/local/lib/python3.11/dist-packages/django/views/generic/base.py", line 104, in view
    return self.dispatch(request, *args, **kwargs)
           ^^^^^^^^^^^^^^^^^^^^^^^^^^^^^^^^^^^^^^^
  File "/usr/local/lib/python3.11/dist-packages/django/views/generic/base.py", line 143, in dispatch
    return handler(request, *args, **kwargs)
           ^^^^^^^^^^^^^^^^^^^^^^^^^^^^^^^^^
  File "/home/secretdiscorder/djavy/bima/views.py", line 27, in get
    file_path = os.path.join(static_dir, filename)
                ^^
NameError: name 'os' is not defined
Not Found: /bg.jpeg
Not Found: /bg.jpeg
Not Found: /favicon.ico
Not Found: /bg.jpeg
Not Found: /favicon.ico
Internal Server Error: /home/
Traceback (most recent call last):
  File "/home/bima/env/lib/python3.11/site-packages/django/core/handlers/exception.py", line 55, in inner
    response = get_response(request)
               ^^^^^^^^^^^^^^^^^^^^^
  File "/home/bima/env/lib/python3.11/site-packages/django/core/handlers/base.py", line 197, in _get_response
    response = wrapped_callback(request, *callback_args, **callback_kwargs)
               ^^^^^^^^^^^^^^^^^^^^^^^^^^^^^^^^^^^^^^^^^^^^^^^^^^^^^^^^^^^^
  File "/home/bima/env/lib/python3.11/site-packages/django/views/generic/base.py", line 104, in view
    return self.dispatch(request, *args, **kwargs)
           ^^^^^^^^^^^^^^^^^^^^^^^^^^^^^^^^^^^^^^^
  File "/home/bima/env/lib/python3.11/site-packages/django/views/generic/base.py", line 143, in dispatch
    return handler(request, *args, **kwargs)
           ^^^^^^^^^^^^^^^^^^^^^^^^^^^^^^^^^
  File "/home/bima/env/lib/python3.11/site-packages/django/views/generic/list.py", line 174, in get
    context = self.get_context_data()
              ^^^^^^^^^^^^^^^^^^^^^^^
  File "/home/bima/env/lib/python3.11/site-packages/django/views/generic/list.py", line 128, in get_context_data
    paginator, page, queryset, is_paginated = self.paginate_queryset(
                                              ^^^^^^^^^^^^^^^^^^^^^^^
  File "/home/bima/env/lib/python3.11/site-packages/django/views/generic/list.py", line 73, in paginate_queryset
    page = paginator.page(page_number)
           ^^^^^^^^^^^^^^^^^^^^^^^^^^^
  File "/home/bima/env/lib/python3.11/site-packages/django/core/paginator.py", line 89, in page
    number = self.validate_number(number)
             ^^^^^^^^^^^^^^^^^^^^^^^^^^^^
  File "/home/bima/env/lib/python3.11/site-packages/django/core/paginator.py", line 70, in validate_number
    if number > self.num_pages:
                ^^^^^^^^^^^^^^
  File "/home/bima/env/lib/python3.11/site-packages/django/utils/functional.py", line 47, in __get__
    res = instance.__dict__[self.name] = self.func(instance)
                                         ^^^^^^^^^^^^^^^^^^^
  File "/home/bima/env/lib/python3.11/site-packages/django/core/paginator.py", line 116, in num_pages
    if self.count == 0 and not self.allow_empty_first_page:
       ^^^^^^^^^^
  File "/home/bima/env/lib/python3.11/site-packages/django/utils/functional.py", line 47, in __get__
    res = instance.__dict__[self.name] = self.func(instance)
                                         ^^^^^^^^^^^^^^^^^^^
  File "/home/bima/env/lib/python3.11/site-packages/django/core/paginator.py", line 110, in count
    return c()
           ^^^
  File "/home/bima/env/lib/python3.11/site-packages/django/db/models/query.py", line 620, in count
    return self.query.get_count(using=self.db)
           ^^^^^^^^^^^^^^^^^^^^^^^^^^^^^^^^^^^
  File "/home/bima/env/lib/python3.11/site-packages/django/db/models/sql/query.py", line 630, in get_count
    return obj.get_aggregation(using, {"__count": Count("*")})["__count"]
           ^^^^^^^^^^^^^^^^^^^^^^^^^^^^^^^^^^^^^^^^^^^^^^^^^^^
  File "/home/bima/env/lib/python3.11/site-packages/django/db/models/sql/query.py", line 616, in get_aggregation
    result = compiler.execute_sql(SINGLE)
             ^^^^^^^^^^^^^^^^^^^^^^^^^^^^
  File "/home/bima/env/lib/python3.11/site-packages/django/db/models/sql/compiler.py", line 1561, in execute_sql
    sql, params = self.as_sql()
                  ^^^^^^^^^^^^^
  File "/home/bima/env/lib/python3.11/site-packages/django/db/models/sql/compiler.py", line 772, in as_sql
    from_, f_params = self.get_from_clause()
                      ^^^^^^^^^^^^^^^^^^^^^^
  File "/home/bima/env/lib/python3.11/site-packages/django/db/models/sql/compiler.py", line 1141, in get_from_clause
    clause_sql, clause_params = self.compile(from_clause)
                                ^^^^^^^^^^^^^^^^^^^^^^^^^
  File "/home/bima/env/lib/python3.11/site-packages/django/db/models/sql/compiler.py", line 557, in compile
    sql, params = node.as_sql(self, self.connection)
                  ^^^^^^^^^^^^^^^^^^^^^^^^^^^^^^^^^^
  File "/home/bima/env/lib/python3.11/site-packages/django/db/models/sql/datastructures.py", line 220, in as_sql
    base_sql = compiler.quote_name_unless_alias(self.table_name)
               ^^^^^^^^^^^^^^^^^^^^^^^^^^^^^^^^^^^^^^^^^^^^^^^^^
  File "/home/bima/env/lib/python3.11/site-packages/django/db/models/sql/compiler.py", line 548, in quote_name_unless_alias
    r = self.connection.ops.quote_name(name)
        ^^^^^^^^^^^^^^^^^^^^^^^^^^^^^^^^^^^^
  File "/home/bima/env/lib/python3.11/site-packages/django/db/backends/dummy/base.py", line 20, in complain
    raise ImproperlyConfigured(
django.core.exceptions.ImproperlyConfigured: settings.DATABASES is improperly configured. Please supply the ENGINE value. Check settings documentation for more details.
Internal Server Error: /home/
Traceback (most recent call last):
  File "/home/bima/env/lib/python3.11/site-packages/django/core/handlers/exception.py", line 55, in inner
    response = get_response(request)
               ^^^^^^^^^^^^^^^^^^^^^
  File "/home/bima/env/lib/python3.11/site-packages/django/core/handlers/base.py", line 197, in _get_response
    response = wrapped_callback(request, *callback_args, **callback_kwargs)
               ^^^^^^^^^^^^^^^^^^^^^^^^^^^^^^^^^^^^^^^^^^^^^^^^^^^^^^^^^^^^
  File "/home/bima/env/lib/python3.11/site-packages/django/views/generic/base.py", line 104, in view
    return self.dispatch(request, *args, **kwargs)
           ^^^^^^^^^^^^^^^^^^^^^^^^^^^^^^^^^^^^^^^
  File "/home/bima/env/lib/python3.11/site-packages/django/views/generic/base.py", line 143, in dispatch
    return handler(request, *args, **kwargs)
           ^^^^^^^^^^^^^^^^^^^^^^^^^^^^^^^^^
  File "/home/bima/env/lib/python3.11/site-packages/django/views/generic/list.py", line 174, in get
    context = self.get_context_data()
              ^^^^^^^^^^^^^^^^^^^^^^^
  File "/home/bima/env/lib/python3.11/site-packages/django/views/generic/list.py", line 128, in get_context_data
    paginator, page, queryset, is_paginated = self.paginate_queryset(
                                              ^^^^^^^^^^^^^^^^^^^^^^^
  File "/home/bima/env/lib/python3.11/site-packages/django/views/generic/list.py", line 73, in paginate_queryset
    page = paginator.page(page_number)
           ^^^^^^^^^^^^^^^^^^^^^^^^^^^
  File "/home/bima/env/lib/python3.11/site-packages/django/core/paginator.py", line 89, in page
    number = self.validate_number(number)
             ^^^^^^^^^^^^^^^^^^^^^^^^^^^^
  File "/home/bima/env/lib/python3.11/site-packages/django/core/paginator.py", line 70, in validate_number
    if number > self.num_pages:
                ^^^^^^^^^^^^^^
  File "/home/bima/env/lib/python3.11/site-packages/django/utils/functional.py", line 47, in __get__
    res = instance.__dict__[self.name] = self.func(instance)
                                         ^^^^^^^^^^^^^^^^^^^
  File "/home/bima/env/lib/python3.11/site-packages/django/core/paginator.py", line 116, in num_pages
    if self.count == 0 and not self.allow_empty_first_page:
       ^^^^^^^^^^
  File "/home/bima/env/lib/python3.11/site-packages/django/utils/functional.py", line 47, in __get__
    res = instance.__dict__[self.name] = self.func(instance)
                                         ^^^^^^^^^^^^^^^^^^^
  File "/home/bima/env/lib/python3.11/site-packages/django/core/paginator.py", line 110, in count
    return c()
           ^^^
  File "/home/bima/env/lib/python3.11/site-packages/django/db/models/query.py", line 620, in count
    return self.query.get_count(using=self.db)
           ^^^^^^^^^^^^^^^^^^^^^^^^^^^^^^^^^^^
  File "/home/bima/env/lib/python3.11/site-packages/django/db/models/sql/query.py", line 630, in get_count
    return obj.get_aggregation(using, {"__count": Count("*")})["__count"]
           ^^^^^^^^^^^^^^^^^^^^^^^^^^^^^^^^^^^^^^^^^^^^^^^^^^^
  File "/home/bima/env/lib/python3.11/site-packages/django/db/models/sql/query.py", line 616, in get_aggregation
    result = compiler.execute_sql(SINGLE)
             ^^^^^^^^^^^^^^^^^^^^^^^^^^^^
  File "/home/bima/env/lib/python3.11/site-packages/django/db/models/sql/compiler.py", line 1561, in execute_sql
    sql, params = self.as_sql()
                  ^^^^^^^^^^^^^
  File "/home/bima/env/lib/python3.11/site-packages/django/db/models/sql/compiler.py", line 772, in as_sql
    from_, f_params = self.get_from_clause()
                      ^^^^^^^^^^^^^^^^^^^^^^
  File "/home/bima/env/lib/python3.11/site-packages/django/db/models/sql/compiler.py", line 1141, in get_from_clause
    clause_sql, clause_params = self.compile(from_clause)
                                ^^^^^^^^^^^^^^^^^^^^^^^^^
  File "/home/bima/env/lib/python3.11/site-packages/django/db/models/sql/compiler.py", line 557, in compile
    sql, params = node.as_sql(self, self.connection)
                  ^^^^^^^^^^^^^^^^^^^^^^^^^^^^^^^^^^
  File "/home/bima/env/lib/python3.11/site-packages/django/db/models/sql/datastructures.py", line 220, in as_sql
    base_sql = compiler.quote_name_unless_alias(self.table_name)
               ^^^^^^^^^^^^^^^^^^^^^^^^^^^^^^^^^^^^^^^^^^^^^^^^^
  File "/home/bima/env/lib/python3.11/site-packages/django/db/models/sql/compiler.py", line 548, in quote_name_unless_alias
    r = self.connection.ops.quote_name(name)
        ^^^^^^^^^^^^^^^^^^^^^^^^^^^^^^^^^^^^
  File "/home/bima/env/lib/python3.11/site-packages/django/db/backends/dummy/base.py", line 20, in complain
    raise ImproperlyConfigured(
django.core.exceptions.ImproperlyConfigured: settings.DATABASES is improperly configured. Please supply the ENGINE value. Check settings documentation for more details.
Internal Server Error: /home/
Traceback (most recent call last):
  File "/home/bima/env/lib/python3.11/site-packages/django/core/handlers/exception.py", line 55, in inner
    response = get_response(request)
               ^^^^^^^^^^^^^^^^^^^^^
  File "/home/bima/env/lib/python3.11/site-packages/django/core/handlers/base.py", line 197, in _get_response
    response = wrapped_callback(request, *callback_args, **callback_kwargs)
               ^^^^^^^^^^^^^^^^^^^^^^^^^^^^^^^^^^^^^^^^^^^^^^^^^^^^^^^^^^^^
  File "/home/bima/env/lib/python3.11/site-packages/django/views/generic/base.py", line 104, in view
    return self.dispatch(request, *args, **kwargs)
           ^^^^^^^^^^^^^^^^^^^^^^^^^^^^^^^^^^^^^^^
  File "/home/bima/env/lib/python3.11/site-packages/django/views/generic/base.py", line 143, in dispatch
    return handler(request, *args, **kwargs)
           ^^^^^^^^^^^^^^^^^^^^^^^^^^^^^^^^^
  File "/home/bima/env/lib/python3.11/site-packages/django/views/generic/list.py", line 174, in get
    context = self.get_context_data()
              ^^^^^^^^^^^^^^^^^^^^^^^
  File "/home/bima/env/lib/python3.11/site-packages/django/views/generic/list.py", line 128, in get_context_data
    paginator, page, queryset, is_paginated = self.paginate_queryset(
                                              ^^^^^^^^^^^^^^^^^^^^^^^
  File "/home/bima/env/lib/python3.11/site-packages/django/views/generic/list.py", line 73, in paginate_queryset
    page = paginator.page(page_number)
           ^^^^^^^^^^^^^^^^^^^^^^^^^^^
  File "/home/bima/env/lib/python3.11/site-packages/django/core/paginator.py", line 89, in page
    number = self.validate_number(number)
             ^^^^^^^^^^^^^^^^^^^^^^^^^^^^
  File "/home/bima/env/lib/python3.11/site-packages/django/core/paginator.py", line 70, in validate_number
    if number > self.num_pages:
                ^^^^^^^^^^^^^^
  File "/home/bima/env/lib/python3.11/site-packages/django/utils/functional.py", line 47, in __get__
    res = instance.__dict__[self.name] = self.func(instance)
                                         ^^^^^^^^^^^^^^^^^^^
  File "/home/bima/env/lib/python3.11/site-packages/django/core/paginator.py", line 116, in num_pages
    if self.count == 0 and not self.allow_empty_first_page:
       ^^^^^^^^^^
  File "/home/bima/env/lib/python3.11/site-packages/django/utils/functional.py", line 47, in __get__
    res = instance.__dict__[self.name] = self.func(instance)
                                         ^^^^^^^^^^^^^^^^^^^
  File "/home/bima/env/lib/python3.11/site-packages/django/core/paginator.py", line 110, in count
    return c()
           ^^^
  File "/home/bima/env/lib/python3.11/site-packages/django/db/models/query.py", line 620, in count
    return self.query.get_count(using=self.db)
           ^^^^^^^^^^^^^^^^^^^^^^^^^^^^^^^^^^^
  File "/home/bima/env/lib/python3.11/site-packages/django/db/models/sql/query.py", line 630, in get_count
    return obj.get_aggregation(using, {"__count": Count("*")})["__count"]
           ^^^^^^^^^^^^^^^^^^^^^^^^^^^^^^^^^^^^^^^^^^^^^^^^^^^
  File "/home/bima/env/lib/python3.11/site-packages/django/db/models/sql/query.py", line 616, in get_aggregation
    result = compiler.execute_sql(SINGLE)
             ^^^^^^^^^^^^^^^^^^^^^^^^^^^^
  File "/home/bima/env/lib/python3.11/site-packages/django/db/models/sql/compiler.py", line 1561, in execute_sql
    sql, params = self.as_sql()
                  ^^^^^^^^^^^^^
  File "/home/bima/env/lib/python3.11/site-packages/django/db/models/sql/compiler.py", line 772, in as_sql
    from_, f_params = self.get_from_clause()
                      ^^^^^^^^^^^^^^^^^^^^^^
  File "/home/bima/env/lib/python3.11/site-packages/django/db/models/sql/compiler.py", line 1141, in get_from_clause
    clause_sql, clause_params = self.compile(from_clause)
                                ^^^^^^^^^^^^^^^^^^^^^^^^^
  File "/home/bima/env/lib/python3.11/site-packages/django/db/models/sql/compiler.py", line 557, in compile
    sql, params = node.as_sql(self, self.connection)
                  ^^^^^^^^^^^^^^^^^^^^^^^^^^^^^^^^^^
  File "/home/bima/env/lib/python3.11/site-packages/django/db/models/sql/datastructures.py", line 220, in as_sql
    base_sql = compiler.quote_name_unless_alias(self.table_name)
               ^^^^^^^^^^^^^^^^^^^^^^^^^^^^^^^^^^^^^^^^^^^^^^^^^
  File "/home/bima/env/lib/python3.11/site-packages/django/db/models/sql/compiler.py", line 548, in quote_name_unless_alias
    r = self.connection.ops.quote_name(name)
        ^^^^^^^^^^^^^^^^^^^^^^^^^^^^^^^^^^^^
  File "/home/bima/env/lib/python3.11/site-packages/django/db/backends/dummy/base.py", line 20, in complain
    raise ImproperlyConfigured(
django.core.exceptions.ImproperlyConfigured: settings.DATABASES is improperly configured. Please supply the ENGINE value. Check settings documentation for more details.
Not Found: /favicon.ico
Not Found: /bg.jpeg
Not Found: /base/bg.jpeg
Not Found: /base/favicon.ico
Not Found: /bg.jpeg
Not Found: /base/bg.jpeg
Not Found: /base/favicon.ico
Not Found: /bg.jpeg
Not Found: /base/bg.jpeg
Not Found: /bg.jpeg
Not Found: /favicon.ico
Not Found: /base/bg.jpeg
Not Found: /bg.jpeg
Not Found: /favicon.ico
Not Found: /base/bg.jpeg
Not Found: /base/favicon.ico
Not Found: /favicon.ico
Not Found: /bg.jpeg
Not Found: /base/bg.jpeg
Not Found: /base/favicon.ico
Not Found: /bg.jpeg
Not Found: /favicon.ico
Not Found: /base/bg.jpeg
Not Found: /base/favicon.ico
Not Found: /favicon.ico
